Traceback (most recent call last):
  File "C:\Users\staci\anaconda3\lib\site-packages\jupyter_cache\executors\utils.py", line 64, in single_nb_execution
    **kwargs,
  File "C:\Users\staci\anaconda3\lib\site-packages\nbclient\client.py", line 1204, in execute
    return NotebookClient(nb=nb, resources=resources, km=km, **kwargs).execute()
  File "C:\Users\staci\anaconda3\lib\site-packages\nbclient\util.py", line 84, in wrapped
    return just_run(coro(*args, **kwargs))
  File "C:\Users\staci\anaconda3\lib\site-packages\nbclient\util.py", line 62, in just_run
    return loop.run_until_complete(coro)
  File "C:\Users\staci\anaconda3\lib\asyncio\base_events.py", line 587, in run_until_complete
    return future.result()
  File "C:\Users\staci\anaconda3\lib\site-packages\nbclient\client.py", line 664, in async_execute
    cell, index, execution_count=self.code_cells_executed + 1
  File "C:\Users\staci\anaconda3\lib\site-packages\nbclient\client.py", line 965, in async_execute_cell
    await self._check_raise_for_error(cell, cell_index, exec_reply)
  File "C:\Users\staci\anaconda3\lib\site-packages\nbclient\client.py", line 862, in _check_raise_for_error
    raise CellExecutionError.from_cell_and_msg(cell, exec_reply_content)
nbclient.exceptions.CellExecutionError: An error occurred while executing the following cell:
------------------
# Function for PCA
def RunPCA(df, cat_feat, num_feat, n_comp):
    # One-hot Encoding
    enc1 = OneHotEncoder()
    enc_feat = enc1.fit_transform(df[cat_feat])

    # Combine encoded categorical features and numerical features
    proc_feat = np.concatenate((enc_feat.toarray(), df[num_feat]), axis=1)

    # Scaler for Process Features
    sca1 = StandardScaler()
    scal_feat = sca1.fit_transform(proc_feat)

    # Get PCA
    pca = PCA(n_components = n_comp)
    pri_comp = pca.fit_transform(scaled_features)

    # Data Frame for Principal Components
    df_prin = pd.DataFrame(data=pri_comp, columns=[c1 for c1 in range(1, n_comp+1)])
    
    # Check Ratio
    EVR = pca.explained_variance_ratio_
    print("Explained Variance Ratio:", EVR)

    # Plot
    plt.bar([c1 for c1 in range(1, n_comp+1)], EVR)
    plt.xlabel('Principal Components')
    plt.ylabel('Explained Variance Ratio (EVR)')
    plt.title('Explained Variance Ratio (EVR) by Principal Component')
    plt.show()

    return df_prin

cat_feat = ['neighbourhood', 'room_type']
num_feat = ['price', 'minimum_nights', 'number_of_reviews']

df_prin = RunPCA(df_unique, cat_feat, num_feat, n_comp=5)
------------------

[1;31m---------------------------------------------------------------------------[0m
[1;31mNameError[0m                                 Traceback (most recent call last)
[1;32m~\AppData\Local\Temp\ipykernel_17456\736602038.py[0m in [0;36m<module>[1;34m[0m
[0;32m     35[0m [0mnum_feat[0m [1;33m=[0m [1;33m[[0m[1;34m'price'[0m[1;33m,[0m [1;34m'minimum_nights'[0m[1;33m,[0m [1;34m'number_of_reviews'[0m[1;33m][0m[1;33m[0m[1;33m[0m[0m
[0;32m     36[0m [1;33m[0m[0m
[1;32m---> 37[1;33m [0mdf_prin[0m [1;33m=[0m [0mRunPCA[0m[1;33m([0m[0mdf_unique[0m[1;33m,[0m [0mcat_feat[0m[1;33m,[0m [0mnum_feat[0m[1;33m,[0m [0mn_comp[0m[1;33m=[0m[1;36m5[0m[1;33m)[0m[1;33m[0m[1;33m[0m[0m
[0m
[1;32m~\AppData\Local\Temp\ipykernel_17456\736602038.py[0m in [0;36mRunPCA[1;34m(df, cat_feat, num_feat, n_comp)[0m
[0;32m     14[0m     [1;31m# Get PCA[0m[1;33m[0m[1;33m[0m[1;33m[0m[0m
[0;32m     15[0m     [0mpca[0m [1;33m=[0m [0mPCA[0m[1;33m([0m[0mn_components[0m [1;33m=[0m [0mn_comp[0m[1;33m)[0m[1;33m[0m[1;33m[0m[0m
[1;32m---> 16[1;33m     [0mpri_comp[0m [1;33m=[0m [0mpca[0m[1;33m.[0m[0mfit_transform[0m[1;33m([0m[0mscaled_features[0m[1;33m)[0m[1;33m[0m[1;33m[0m[0m
[0m[0;32m     17[0m [1;33m[0m[0m
[0;32m     18[0m     [1;31m# Data Frame for Principal Components[0m[1;33m[0m[1;33m[0m[1;33m[0m[0m

[1;31mNameError[0m: name 'scaled_features' is not defined
NameError: name 'scaled_features' is not defined

