Traceback (most recent call last):
  File "C:\Users\staci\anaconda3\lib\site-packages\jupyter_cache\executors\utils.py", line 64, in single_nb_execution
    **kwargs,
  File "C:\Users\staci\anaconda3\lib\site-packages\nbclient\client.py", line 1204, in execute
    return NotebookClient(nb=nb, resources=resources, km=km, **kwargs).execute()
  File "C:\Users\staci\anaconda3\lib\site-packages\nbclient\util.py", line 84, in wrapped
    return just_run(coro(*args, **kwargs))
  File "C:\Users\staci\anaconda3\lib\site-packages\nbclient\util.py", line 62, in just_run
    return loop.run_until_complete(coro)
  File "C:\Users\staci\anaconda3\lib\asyncio\base_events.py", line 587, in run_until_complete
    return future.result()
  File "C:\Users\staci\anaconda3\lib\site-packages\nbclient\client.py", line 664, in async_execute
    cell, index, execution_count=self.code_cells_executed + 1
  File "C:\Users\staci\anaconda3\lib\site-packages\nbclient\client.py", line 965, in async_execute_cell
    await self._check_raise_for_error(cell, cell_index, exec_reply)
  File "C:\Users\staci\anaconda3\lib\site-packages\nbclient\client.py", line 862, in _check_raise_for_error
    raise CellExecutionError.from_cell_and_msg(cell, exec_reply_content)
nbclient.exceptions.CellExecutionError: An error occurred while executing the following cell:
------------------
# Assign Event
df_med = df[df['Event'] == "Athletics Men's Marathon"]

# Obtain histograms and Box Plots
for col in ['Age', 'Weight', 'Height']:
    histBox(df_narr)
------------------

[1;31m---------------------------------------------------------------------------[0m
[1;31mNameError[0m                                 Traceback (most recent call last)
[1;32m~\AppData\Local\Temp\ipykernel_2592\2636939246.py[0m in [0;36m<module>[1;34m[0m
[0;32m      4[0m [1;31m# Obtain histograms and Box Plots[0m[1;33m[0m[1;33m[0m[1;33m[0m[0m
[0;32m      5[0m [1;32mfor[0m [0mcol[0m [1;32min[0m [1;33m[[0m[1;34m'Age'[0m[1;33m,[0m [1;34m'Weight'[0m[1;33m,[0m [1;34m'Height'[0m[1;33m][0m[1;33m:[0m[1;33m[0m[1;33m[0m[0m
[1;32m----> 6[1;33m     [0mhistBox[0m[1;33m([0m[0mdf_narr[0m[1;33m)[0m[1;33m[0m[1;33m[0m[0m
[0m
[1;31mNameError[0m: name 'df_narr' is not defined
NameError: name 'df_narr' is not defined

